<mujoco model="smpl-x-robot">
    <!--  
            Robot Intelligence Lab
            SMPL-X Robot model
            
            @ Contact us : taemoon-jeong (taemoon-jeong@korea.ac.kr)
    -->
    <compiler  inertiafromgeom="true" angle="radian"/>

    <default>
        <joint limited="true" damping="1" armature="0"/>
        <geom contype="1" condim="3" margin="0.001" solref=".02 1" solimp=".8 .8 .01" material="matgeom"/>
        <motor ctrlrange="-.4 .4" ctrllimited="true"/>
    </default>

    <option timestep="0.005" iterations="50" tolerance="1e-10" solver="Newton" jacobian="dense" cone="pyramidal"/>
    <size nconmax="50" njmax="200" nstack="10000"/>

    <visual>
        <map force="0.1" zfar="30"/>
        <rgba haze="0.15 0.25 0.35 1"/>
        <quality shadowsize="2048"/>
        <global offwidth="800" offheight="800"/>
    </visual>

    <asset>
        <texture name="texgeom" type="cube" builtin="flat" mark="cross" width="127" height="1278" 
            rgb1="0.8 0.6 0.4" rgb2="0.8 0.6 0.4" markrgb="1 1 1" random="0.01"/>  
        <material name="matgeom" texture="texgeom" texuniform="true" rgba="0.8 0.6 0.4 1.0"/>
        <material name="self" rgba=".7 .5 .3 1"/>
        <texture name="blue_grid" type="2d" builtin="checker" rgb1=".02 .14 .44" rgb2=".27 .55 1" width="300" height="300" mark="edge" markrgb="1 1 1"/>
        <material name="blue_grid" texture="blue_grid" texrepeat="1 1" texuniform="true" reflectance=".2"/>
            <!-- Sky -->
        <texture type="skybox" builtin="gradient" rgb1="0.1 0.2 0.3" rgb2="0 0 0" width="512"
            height="3072" />
        <!-- Ground -->
        <texture type="2d" name="groundplane" builtin="checker" mark="edge" rgb1="0.3 0.4 0.5"
            rgb2="0.1 0.2 0.3" markrgb="0.8 0.8 0.8" width="300" height="300" />
        <material name="groundplane" texture="groundplane" texuniform="true" texrepeat="2 2"
            reflectance="0.2" />
    </asset>

    <worldbody>
        <light pos="0 0 3" dir="0 0 -1" directional="true" diffuse="1 1 1"/>
        <geom name="floor" type="plane" conaffinity="1" size="50 50 .05" material="blue_grid"/>
        <body name="base" pos="0 0 0.95">
            <freejoint name="base"/>
            <geom name="base" type="sphere" pos="0 0 0" size="0.06"/>
            <body name="pelvis" pos="0 0 0" euler="0 0 0" >
                <geom name="base2lpelvis" type="capsule" fromto="0 0 0 -0.006815334782004356 0.06951973587274551 -0.09140622615814209"  size="0.04" />
                <geom name="base2rpelvis" type="capsule" fromto="0 0 0 -0.004319818690419197 -0.06767047941684723 -0.09052169322967529"  size="0.04" />
                <joint name="pelvis1" type="hinge" pos="0 0 0" axis="1 0 0" range="-3.141592 3.141592" damping="60" stiffness="0" armature="0.02" />
                <joint name="pelvis2" type="hinge" pos="0 0 0" axis="0 1 0" range="-3.141592 3.141592" damping="60" stiffness="0" armature="0.02" />
                <joint name="pelvis3" type="hinge" pos="0 0 0" axis="0 0 1" range="-3.141592 3.141592" damping="60" stiffness="0" armature="0.02" />
                
                <body name="left_hip" pos="-0.006815334782004356 0.06951973587274551 -0.09140622615814209" euler="0 0 0">
                    <geom name="lhip2lknee" type="capsule" fromto="0 0 0 -0.004495806992 0.03427654505 -0.3751985729"  size="0.04" />
                    <joint name="l_hip1" type="hinge" pos="0 0 0" axis="1 0 0" range="-3.141592 3.141592" damping="30" stiffness="0" armature="0.01" />
                    <joint name="l_hip2" type="hinge" pos="0 0 0" axis="0 1 0" range="-3.141592 3.141592" damping="30" stiffness="0" armature="0.01" />
                    <joint name="l_hip3" type="hinge" pos="0 0 0" axis="0 0 1" range="-3.141592 3.141592" damping="30" stiffness="0" armature="0.01" />
                    
                    <body name="left_knee" pos="-0.004495806992 0.03427654505 -0.3751985729" euler="0 0 0">
                        <geom name="lknee2lankle" type="capsule" fromto="0 0 0 -0.04369332828 -0.01359570026 -0.3979604542"  size="0.04" />
                        <joint name="l_knee" type="hinge" pos="0 0 0" axis="0 1 0" range="0.0175 2.0944" damping="30" stiffness="0" armature="0.0060" />
                        
                        <body name="left_ankle" pos="-0.04369332828 -0.01359570026 -0.3979604542" euler="0 0 0">
                            <geom name="lankle" type="box" pos="0 0 -0.025" size="0.03 0.03 0.025" />
                            <geom name="lfoot" type="box" pos="0.03 0 -0.05" size="0.1 0.05 0.015" />
                            <joint name="l_ankle1" type="hinge" pos="0 0 0" axis="0 1 0" range="-3.141592 3.141592" stiffness="0" damping="20" armature="0.0008" />
                            <joint name="l_ankle2" type="hinge" pos="0 0 0" axis="1 0 0" range="-3.141592 3.141592" stiffness="0" damping="20" armature="0.0006" />
                            <joint name="l_ankle3" type="hinge" pos="0 0 0" axis="0 0 1" range="-0.52333333333 0.52333333333" stiffness="0" damping="20" armature="0.0006" />
                        </body>
                    </body>
                </body>

                <body name="right_hip" pos="-0.006815334782004356 -0.06951973587274551 -0.09140622615814209" euler="0 0 0">
                    <geom name="rhip2rknee" type="capsule" fromto="0 0 0 -0.004495806992 -0.03427654505 -0.3751985729"  size="0.04" />
                    <joint name="r_hip1" type="hinge" pos="0 0 0" axis="1 0 0" range="-3.141592 3.141592" damping="30" stiffness="0" armature="0.01" />
                    <joint name="r_hip2" type="hinge" pos="0 0 0" axis="0 1 0" range="-3.141592 3.141592" damping="30" stiffness="0" armature="0.01" />
                    <joint name="r_hip3" type="hinge" pos="0 0 0" axis="0 0 1" range="-3.141592 3.141592" damping="30" stiffness="0" armature="0.01" />
                    <body name="right_knee" pos="-0.004495806992 -0.03427654505 -0.3751985729" euler="0 0 0">
                        <geom name="rknee2rankle" type="capsule" fromto="0 0 0 -0.04369332828 0.01359570026 -0.3979604542"  size="0.04" />
                        <joint name="r_knee" type="hinge" pos="0 0 0" axis="0 1 0" range="0.0175 2.0944" damping="30" stiffness="0" armature="0.0060" />
                        <body name="right_ankle" pos="-0.04369332828 0.01359570026 -0.3979604542" euler="0 0 0">
                            <geom name="rankle" type="box" pos="0 0 -0.025" size="0.03 0.03 0.025" />
                            <geom name="rfoot" type="box" pos="0.03 0 -0.05" size="0.1 0.05 0.015" />
                            <joint name="r_ankle1" type="hinge" pos="0 0 0" axis="0 1 0" range="-3.141592 3.141592" stiffness="0" damping="20" armature="0.0008" />
                            <joint name="r_ankle2" type="hinge" pos="0 0 0" axis="1 0 0" range="-3.141592 3.141592" stiffness="0" damping="20" armature="0.0006" />
                            <joint name="r_ankle3" type="hinge" pos="0 0 0" axis="0 0 1" range="-0.52333333333 0.52333333333" stiffness="0" damping="20" armature="0.0006" />
                        </body>
                    </body>
                </body>

                <geom name="base2spine1" type="capsule" fromto="0 0 0 -0.02669631317257881 -0.00253287423402071 0.10896323621273041"  size="0.04" density="2226"/>
                <body name="spine1" pos="-0.02669631317257881 -0.00253287423402071 0.10896323621273041" euler="0 0 0">
                    <geom name="spine2spine" type="capsule" fromto="0 0 0 0.001092471182 0.005487040151 0.1351804286"  size="0.04" density="2226"/>
                    <joint name="spine1-1" type="hinge" pos="0 0 0" axis="0 1 0" range="-3.141592 3.141592" damping="60" stiffness="0" armature="0.02" />
                    <joint name="spine1-2" type="hinge" pos="0 0 0" axis="1 0 0" range="-3.141592 3.141592" damping="60" stiffness="0" armature="0.02" />                   
                    <joint name="spine1-3" type="hinge" pos="0 0 0" axis="0 0 1" range="-3.141592 3.141592" damping="60" stiffness="0" armature="0.02" />

                    <body name="spine2" pos="0.001092471182 0.005487040151 0.1351804286" euler="0 0 0">
                        <geom name="spine2spine2" type="capsule" fromto="0 0 0 0.02542456612 0.001456997823 0.05292221904"  size="0.04" density="2226"/>
                        <joint name="spine2-1" type="hinge" pos="0 0 0" axis="0 1 0" range="-3.141592 3.141592" damping="60" stiffness="0" armature="0.02" />
                        <joint name="spine2-2" type="hinge" pos="0 0 0" axis="1 0 0" range="-3.141592 3.141592" damping="60" stiffness="0" armature="0.02" />                   
                        <joint name="spine2-3" type="hinge" pos="0 0 0" axis="0 0 1" range="-3.141592 3.141592" damping="60" stiffness="0" armature="0.02" />


                        <body name="spine3" pos="0.02542456612 0.001456997823 0.05292221904" euler="0 0 0">
                            <geom name="spine2spine3" type="capsule" fromto="0 0 0 -0.04285703227 -0.002778389724 0.2138703763"  size="0.04" density="2226"/>
                            <joint name="spine3-1" type="hinge" pos="0 0 0" axis="0 1 0" range="-3.141592 3.141592" damping="60" stiffness="0" armature="0.02" />
                            <joint name="spine3-2" type="hinge" pos="0 0 0" axis="1 0 0" range="-3.141592 3.141592" damping="60" stiffness="0" armature="0.02" />                   
                            <joint name="spine3-3" type="hinge" pos="0 0 0" axis="0 0 1" range="-3.141592 3.141592" damping="60" stiffness="0" armature="0.02" />


                            <body name="neck" pos="-0.04285703227 -0.002778389724 0.2138703763" euler="0 0 0">
                                <geom name="neck2head" type="capsule" fromto="0 0 0 0.05134896934 0.00515184016 0.0649696588"  size="0.04" />
                                <joint name="neck1" type="hinge" pos="0 0 0" axis="1 0 0" range="-3.141592 3.141592" damping="5" stiffness="0" armature="0.02" />
                                <joint name="neck2" type="hinge" pos="0 0 0" axis="0 1 0" range="-3.141592 3.141592" damping="5" stiffness="0" armature="0.02" />
                                <joint name="neck3" type="hinge" pos="0 0 0" axis="0 0 1" range="-3.141592 3.141592" damping="5" stiffness="0" armature="0.02" />

                                <body name="head" pos="0.05134896934 0.00515184016 0.06496965885" euler="0 0 0">
                                    <geom name="head" type="box" pos="0 0  0.06496965885" size="0.06 0.06 0.07" />
                                    <geom name="nose" type="box" pos="0.05 0  0.06496965885" size="0.05 0.02 0.02" />
                                    <joint name="head1" type="hinge" pos="0 0 0" axis="1 0 0" range="-3.141592 3.141592" damping="5" stiffness="0" armature="0.02" />
                                    <joint name="head2" type="hinge" pos="0 0 0" axis="0 1 0" range="-3.141592 3.141592" damping="5" stiffness="0" armature="0.02" />
                                    <joint name="head3" type="hinge" pos="0 0 0" axis="0 0 1" range="-3.141592 3.141592" damping="5" stiffness="0" armature="0.02" />
                                </body>
                            </body>

                            <geom name="spine2lcollar" type="capsule" fromto="0 0 0 -0.03408960626 0.07884474564 0.1217493117"  size="0.04" />
                            <body name="left_collar" pos="-0.03408960626 0.07884474564 0.1217493117" euler="0 0 0">
                                <geom name="lcollar2lshoulder" type="capsule" fromto="0 0 0 -0.008868150413 0.09097691625 0.03046888113"  size="0.04" />
                                <joint name="l_collar1" type="hinge" pos="0 0 0" axis="1 0 0" range="-3.141592 3.141592" stiffness="0" damping="20" armature="0.0068" />
                                <joint name="l_collar2" type="hinge" pos="0 0 0" axis="0 0 1" range="-3.141592 3.141592" stiffness="0" damping="20" armature="0.0051" />
                                <joint name="l_collar3" type="hinge" pos="0 0 0" axis="0 1 0" range="-3.141592 3.141592" stiffness="0" damping="20" armature="0.0051" />
                                
                                <body name="left_shoulder" pos="-0.008868150413 0.09097691625 0.03046888113" euler="0 0 0">
                                    <geom name="lshoulder2lelbow" type="capsule" fromto="0 0 0 -0.02745642886 0.2596122175 -0.01277205348"  size="0.04" />
                                    <joint name="l_shoulder1" type="hinge" pos="0 0 0" axis="1 0 0" range="-3.141592 3.141592" stiffness="0" damping="20" armature="0.0068" />
                                    <joint name="l_shoulder2" type="hinge" pos="0 0 0" axis="0 0 1" range="-3.141592 3.141592" stiffness="0" damping="20" armature="0.0051" />
                                    <joint name="l_shoulder3" type="hinge" pos="0 0 0" axis="0 1 0" range="-3.141592 3.141592" stiffness="0" damping="20" armature="0.0051" />
                                    
                                    <body name="left_elbow" pos="-0.02745642886 0.2596122175 -0.01277205348" euler="0 0 0">
                                        <geom name="lelbow2lwrist" type="capsule" fromto="0 0 0 -0.001170918345 0.2492336035 0.008986026049"  size="0.04" />
                                        <joint name="l_elbow" type="hinge" pos="0 0 0" axis="0 0 1" range="-2.61666666667 -0.01" stiffness="0" damping="15" armature="0.0028" />
                                        
                                        <body name="left_wrist" pos="-0.001170918345 0.2492336035 0.008986026049" euler="0 0 0">
                                            <geom name="lwrist2lindex1" type="capsule" fromto="0 0 0 0.01935114339 0.1019018292 -0.008688151836"  size="0.006" />
                                            <geom name="lwrist2lmiddle1" type="capsule" fromto="0 0 0 -0.00398080796 0.1093975306 -0.006327688694"  size="0.006" />
                                            <geom name="lwrist2lpinky1" type="capsule" fromto="0 0 0 -0.04374960065 0.08404684067 -0.0145393312"  size="0.006" />
                                            <geom name="lwrist2lring1" type="capsule" fromto="0 0 0 -0.02734463662 0.09744417667 -0.009267628193"  size="0.006" />
                                            <geom name="lwrist2lthumb1" type="capsule" fromto="0 0 0 0.02561088279 0.0406357646 -0.01797673106"  size="0.006" />
                                            
                                            <joint name="l_wrist1" type="hinge" pos="0 0 0" axis="0 1 0" range="-3.141592 3.141592" damping="5" stiffness="0" armature="0.02" />
                                            <joint name="l_wrist2" type="hinge" pos="0 0 0" axis="0 0 1" range="-3.141592 3.141592" damping="5" stiffness="0" armature="0.02" />
                                            <joint name="l_wrist3" type="hinge" pos="0 0 0" axis="1 0 0" range="-3.141592 3.141592" damping="5" stiffness="0" armature="0.02" />
                                        
                                            <body name="left_index1" pos="0.01935114339 0.1019018292 -0.008688151836" euler="0 0 0">
                                                <geom name="lindex1-lindex2" type="capsule" fromto="0 0 0 0.001150548458 0.0301489234 -0.01115390658"  size="0.006" />
                                                <joint name="l_index1" type="hinge" pos="0 0 0" axis="0 1 0" range="-3.141592 3.141592" damping="5" stiffness="0" armature="0.02" />
                                                <joint name="l_index2" type="hinge" pos="0 0 0" axis="0 0 1" range="-3.141592 3.141592" damping="5" stiffness="0" armature="0.02" />
                                                <joint name="l_index3" type="hinge" pos="0 0 0" axis="1 0 0" range="-3.141592 3.141592" damping="5" stiffness="0" armature="0.02" />
                                        
                                                <body name="left_index2" pos="0.001150548458 0.0301489234 -0.01115390658" euler="0 0 0">
                                                    <geom name="lindex2-lindex3" type="capsule" fromto="0 0 0 -0.00243325904 0.006504237652 -0.02157706022"  size="0.006" />
                                                    <joint name="l_index2-1" type="hinge" pos="0 0 0" axis="0 1 0" range="-3.141592 3.141592" damping="5" stiffness="0" armature="0.02" />
                                                    <joint name="l_index2-2" type="hinge" pos="0 0 0" axis="0 0 1" range="-3.141592 3.141592" damping="5" stiffness="0" armature="0.02" />
                                                    <joint name="l_index2-3" type="hinge" pos="0 0 0" axis="1 0 0" range="-3.141592 3.141592" damping="5" stiffness="0" armature="0.02" />
                
                                                    <body name="left_index3" pos="-0.00243325904 0.006504237652 -0.02157706022" euler="0 0 0">
                                                        <!-- temporary geom value for finger tip -->
                                                        <geom name="lindex3-lindextip" type="capsule" fromto="0 0 0 -0.002 0.006 -0.02"  size="0.006" />
                                                        <joint name="l_index3-1" type="hinge" pos="0 0 0" axis="0 1 0" range="-3.141592 3.141592" damping="5" stiffness="0" armature="0.02" />
                                                        <joint name="l_index3-2" type="hinge" pos="0 0 0" axis="0 0 1" range="-3.141592 3.141592" damping="5" stiffness="0" armature="0.02" />
                                                        <joint name="l_index3-3" type="hinge" pos="0 0 0" axis="1 0 0" range="-3.141592 3.141592" damping="5" stiffness="0" armature="0.02" />
                                                        <body name="left_index4" pos="-0.002 0.006 -0.02" euler="0 0 0"/>
                                                    </body>
                                                </body>
                                            </body>
                                            <body name="left_middle1" pos="-0.00398080796 0.1093975306 -0.006327688694" euler="0 0 0">
                                                <geom name="lmiddle1-lmiddle2" type="capsule" fromto="0 0 0 -0.004641152918 0.02647173405 -0.01521787047"  size="0.006" />
                                                <joint name="l_middle1" type="hinge" pos="0 0 0" axis="0 1 0" range="-3.141592 3.141592" damping="5" stiffness="0" armature="0.02" />
                                                <joint name="l_middle2" type="hinge" pos="0 0 0" axis="0 0 1" range="-3.141592 3.141592" damping="5" stiffness="0" armature="0.02" />
                                                <joint name="l_middle3" type="hinge" pos="0 0 0" axis="1 0 0" range="-3.141592 3.141592" damping="5" stiffness="0" armature="0.02" />
                                        
                                                <body name="left_middle2" pos="-0.004641152918 0.02647173405 -0.01521787047" euler="0 0 0">
                                                    <geom name="lmiddle2-lmiddle3" type="capsule" fromto="0 0 0 -0.001911483705 0.005021989346 -0.02334663272"  size="0.006" />
                                                    <joint name="l_middle2-1" type="hinge" pos="0 0 0" axis="0 1 0" range="-3.141592 3.141592" damping="5" stiffness="0" armature="0.02" />
                                                    <joint name="l_middle2-2" type="hinge" pos="0 0 0" axis="0 0 1" range="-3.141592 3.141592" damping="5" stiffness="0" armature="0.02" />
                                                    <joint name="l_middle2-3" type="hinge" pos="0 0 0" axis="1 0 0" range="-3.141592 3.141592" damping="5" stiffness="0" armature="0.02" />
                                        
                                                    <body name="left_middle3" pos="-0.001911483705 0.005021989346 -0.02334663272" euler="0 0 0">
                                                        <geom name="lmiddl3-lmiddletip" type="capsule" fromto="0 0 0 -0.0019 0.005 -0.02"  size="0.006" />
                                                        <joint name="l_middle3-1" type="hinge" pos="0 0 0" axis="0 1 0" range="-3.141592 3.141592" damping="5" stiffness="0" armature="0.02" />
                                                        <joint name="l_middle3-2" type="hinge" pos="0 0 0" axis="0 0 1" range="-3.141592 3.141592" damping="5" stiffness="0" armature="0.02" />
                                                        <joint name="l_middle3-3" type="hinge" pos="0 0 0" axis="1 0 0" range="-3.141592 3.141592" damping="5" stiffness="0" armature="0.02" />
                                                        <body name="left_middle4" pos="-0.0019 0.005 -0.02" euler="0 0 0"/>
                                                    </body>
                                                </body>
                                            </body>
                                            <body name="left_ring1" pos="-0.02734463662 0.09744417667 -0.009267628193" euler="0 0 0">
                                                <geom name="lring1-lring2" type="capsule" fromto="0 0 0 -0.001894921064 0.02356153727 -0.01605704427"  size="0.006" />
                                                <joint name="l_ring1" type="hinge" pos="0 0 0" axis="0 1 0" range="-3.141592 3.141592" damping="5" stiffness="0" armature="0.02" />
                                                <joint name="l_ring2" type="hinge" pos="0 0 0" axis="0 0 1" range="-3.141592 3.141592" damping="5" stiffness="0" armature="0.02" />
                                                <joint name="l_ring3" type="hinge" pos="0 0 0" axis="1 0 0" range="-3.141592 3.141592" damping="5" stiffness="0" armature="0.02" />
                                                      
                                                <body name="left_ring2" pos="-0.001894921064 0.02356153727 -0.01605704427" euler="0 0 0">
                                                    <geom name="lring2-lring3" type="capsule" fromto="0 0 0 8.14124942e-4 0.004257023335 -0.0235479176"  size="0.006" />
                                                    <joint name="l_ring2-1" type="hinge" pos="0 0 0" axis="0 1 0" range="-3.141592 3.141592" damping="5" stiffness="0" armature="0.02" />
                                                    <joint name="l_ring2-2" type="hinge" pos="0 0 0" axis="0 0 1" range="-3.141592 3.141592" damping="5" stiffness="0" armature="0.02" />
                                                    <joint name="l_ring2-3" type="hinge" pos="0 0 0" axis="1 0 0" range="-3.141592 3.141592" damping="5" stiffness="0" armature="0.02" />
                                                      
                                                    <body name="left_ring3" pos="8.14124942e-4 0.004257023335 -0.0235479176" euler="0 0 0">
                                                        <geom name="lring3-lringtip" type="capsule" fromto="0 0 0 8.1e-4 0.004 -0.02"  size="0.006" />
                                                        <joint name="l_ring3-1" type="hinge" pos="0 0 0" axis="0 1 0" range="-3.141592 3.141592" damping="5" stiffness="0" armature="0.02" />
                                                        <joint name="l_ring3-2" type="hinge" pos="0 0 0" axis="0 0 1" range="-3.141592 3.141592" damping="5" stiffness="0" armature="0.02" />
                                                        <joint name="l_ring3-3" type="hinge" pos="0 0 0" axis="1 0 0" range="-3.141592 3.141592" damping="5" stiffness="0" armature="0.02" />
                                                        <body name="left_ring4" pos="8.1e-4 0.004 -0.02" euler="0 0 0"/>
                                                    </body>
                                                </body>
                                            </body>
                                            <body name="left_pinky1" pos="-0.04374960065 0.08404684067 -0.0145393312" euler="0 0 0">
                                                <geom name="lpinky1-lpinky2" type="capsule" fromto="0 0 0 -0.005374751985 0.01212376356 -0.01444780827"  size="0.006" />
                                                <joint name="l_pinky1" type="hinge" pos="0 0 0" axis="0 1 0" range="-3.141592 3.141592" damping="5" stiffness="0" armature="0.02" />
                                                <joint name="l_pinky2" type="hinge" pos="0 0 0" axis="0 0 1" range="-3.141592 3.141592" damping="5" stiffness="0" armature="0.02" />
                                                <joint name="l_pinky3" type="hinge" pos="0 0 0" axis="1 0 0" range="-3.141592 3.141592" damping="5" stiffness="0" armature="0.02" />
                                                                                        
                                                <body name="left_pinky2" pos="-0.005374751985 0.01212376356 -0.01444780827" euler="0 0 0">
                                                    <geom name="lpinky2-lpinky3" type="capsule" fromto="0 0 0 1.66594982e-4 0.003798186779 -0.01885265112"  size="0.006" />
                                                    <joint name="l_pinky2-1" type="hinge" pos="0 0 0" axis="0 1 0" range="-3.141592 3.141592" damping="5" stiffness="0" armature="0.02" />
                                                    <joint name="l_pinky2-2" type="hinge" pos="0 0 0" axis="0 0 1" range="-3.141592 3.141592" damping="5" stiffness="0" armature="0.02" />
                                                    <joint name="l_pinky2-3" type="hinge" pos="0 0 0" axis="1 0 0" range="-3.141592 3.141592" damping="5" stiffness="0" armature="0.02" />
                                                      
                                                    <body name="left_pinky3" pos="1.66594982e-4 0.003798186779 -0.01885265112" euler="0 0 0">
                                                        <geom name="lpinky3-lpinkytip" type="capsule" fromto="0 0 0 1.6e-4 0.003 -0.01"  size="0.006" />
                                                        <joint name="l_pinky3-1" type="hinge" pos="0 0 0" axis="0 1 0" range="-3.141592 3.141592" damping="5" stiffness="0" armature="0.02" />
                                                        <joint name="l_pinky3-2" type="hinge" pos="0 0 0" axis="0 0 1" range="-3.141592 3.141592" damping="5" stiffness="0" armature="0.02" />
                                                        <joint name="l_pinky3-3" type="hinge" pos="0 0 0" axis="1 0 0" range="-3.141592 3.141592" damping="5" stiffness="0" armature="0.02" />
                                                        <body name="left_pinky4" pos="1.6e-4 0.003 -0.01" euler="0 0 0"/>
                                                    </body>
                                                </body>
                                            </body>

                                            <body name="left_thumb1" pos="0.02561088279 0.0406357646 -0.01797673106" euler="0 0 0">
                                                <geom name="lthumb1-lthumb2" type="capsule" fromto="0 0 0 0.01162331179 0.02163672447 -0.01763927937"  size="0.006" />
                                                <joint name="l_thumb1" type="hinge" pos="0 0 0" axis="0 1 0" range="-3.141592 3.141592" damping="5" stiffness="0" armature="0.02" />
                                                <joint name="l_thumb2" type="hinge" pos="0 0 0" axis="0 0 1" range="-3.141592 3.141592" damping="5" stiffness="0" armature="0.02" />
                                                <joint name="l_thumb3" type="hinge" pos="0 0 0" axis="1 0 0" range="-3.141592 3.141592" damping="5" stiffness="0" armature="0.02" />
                                                                                                      
                                                <body name="left_thumb2" pos="0.01162331179 0.02163672447 -0.01763927937" euler="0 0 0">
                                                    <geom name="lthumb2-lthumb3" type="capsule" fromto="0 0 0 0.006547933444 0.02400177717 -0.008356153965"  size="0.006" />
                                                    <joint name="l_thumb2-1" type="hinge" pos="0 0 0" axis="0 1 0" range="-3.141592 3.141592" damping="5" stiffness="0" armature="0.02" />
                                                    <joint name="l_thumb2-2" type="hinge" pos="0 0 0" axis="0 0 1" range="-3.141592 3.141592" damping="5" stiffness="0" armature="0.02" />
                                                    <joint name="l_thumb2-3" type="hinge" pos="0 0 0" axis="1 0 0" range="-3.141592 3.141592" damping="5" stiffness="0" armature="0.02" />
                                                                                                    
                                                    <body name="left_thumb3" pos="0.006547933444 0.02400177717 -0.008356153965" euler="0 0 0">
                                                        <geom name="lthumb3-lthumbtip" type="capsule" fromto="0 0 0 0.006 0.02 -0.008"  size="0.006" />
                                                        <joint name="l_thumb3-1" type="hinge" pos="0 0 0" axis="0 1 0" range="-3.141592 3.141592" damping="5" stiffness="0" armature="0.02" />
                                                        <joint name="l_thumb3-2" type="hinge" pos="0 0 0" axis="0 0 1" range="-3.141592 3.141592" damping="5" stiffness="0" armature="0.02" />
                                                        <joint name="l_thumb3-3" type="hinge" pos="0 0 0" axis="1 0 0" range="-3.141592 3.141592" damping="5" stiffness="0" armature="0.02" />
                                                        <body name="left_thumb4" pos="0.006 0.02 -0.008" euler="0 0 0"/>
                                                    </body>
                                                </body>
                                            </body>
                                        </body>
                                    </body>
                                </body>
                            </body>
                                
                            <geom name="spine2rcollar" type="capsule" fromto="0 0 0 -0.03408960626 -0.07884474564 0.1217493117"  size="0.04" />
                            <body name="right_collar" pos="-0.03408960626 -0.07884474564 0.1217493117" euler="0 0 0">
                                <geom name="rcollar2rshoulder" type="capsule" fromto="0 0 0 -0.008868150413 -0.09097691625 0.03046888113"  size="0.04" />
                                <joint name="r_collar1" type="hinge" pos="0 0 0" axis="1 0 0" range="-3.141592 3.141592" stiffness="0" damping="20" armature="0.0068" />
                                <joint name="r_collar2" type="hinge" pos="0 0 0" axis="0 0 1" range="-3.141592 3.141592" stiffness="0" damping="20" armature="0.0051" />
                                <joint name="r_collar3" type="hinge" pos="0 0 0" axis="0 1 0" range="-3.141592 3.141592" stiffness="0" damping="20" armature="0.0051" />
                                
                                <body name="right_shoulder" pos="-0.008868150413 -0.09097691625 0.03046888113" euler="0 0 0">
                                    <geom name="rshoulder2relbow" type="capsule" fromto="0 0 0 -0.02745642886 -0.2596122175 -0.01277205348"  size="0.04" />
                                    <joint name="r_shoulder1" type="hinge" pos="0 0 0" axis="1 0 0" range="-3.141592 3.141592" stiffness="0" damping="20" armature="0.0068" />
                                    <joint name="r_shoulder2" type="hinge" pos="0 0 0" axis="0 0 1" range="-3.141592 3.141592" stiffness="0" damping="20" armature="0.0051" />
                                    <joint name="r_shoulder3" type="hinge" pos="0 0 0" axis="0 1 0" range="-3.141592 3.141592" stiffness="0" damping="20" armature="0.0051" />
                                    
                                    <body name="right_elbow" pos="-0.02745642886 -0.2596122175 -0.01277205348" euler="0 0 0">
                                        <geom name="relbow2rwrist" type="capsule" fromto="0 0 0 -0.001170918345 -0.2492336035 0.008986026049"  size="0.04" />
                                        <joint name="r_elbow" type="hinge" pos="0 0 0" axis="0 0 1" range="0.01 2.61666666667" stiffness="0" damping="15" armature="0.0028" />
                                        
                                        <body name="right_wrist" pos="-0.001170918345 -0.2492336035 0.008986026049" euler="0 0 0">
                                            <geom name="rwrist2rindex1" type="capsule" fromto="0 0 0 0.0195999369 -0.09988051653 -0.0117828548"  size="0.006" />
                                            <geom name="rwrist2rmiddle1" type="capsule" fromto="0 0 0 -0.003733821213 -0.1073763967 -0.009421944618"  size="0.006" />
                                            <geom name="rwrist2rpinky1" type="capsule" fromto="0 0 0 -0.04350293428 -0.08202672005 -0.01763445139"  size="0.006" />
                                            <geom name="rwrist2rring1" type="capsule" fromto="0 0 0 -0.02709873021 -0.09542346001 -0.01236194372"  size="0.006" />
                                            <geom name="rwrist2rthumb1" type="capsule" fromto="0 0 0 0.02586134896 -0.03861314058 -0.02107441425"  size="0.006" />
                                            
                                            <joint name="r_wrist1" type="hinge" pos="0 0 0" axis="0 1 0" range="-3.141592 3.141592" damping="5" stiffness="0" armature="0.02" />
                                            <joint name="r_wrist2" type="hinge" pos="0 0 0" axis="0 0 1" range="-3.141592 3.141592" damping="5" stiffness="0" armature="0.02" />
                                            <joint name="r_wrist3" type="hinge" pos="0 0 0" axis="1 0 0" range="-3.141592 3.141592" damping="5" stiffness="0" armature="0.02" />
                                            
                                            <body name="right_index1" pos="0.0195999369 -0.09988051653 -0.0117828548" euler="0 0 0">
                                                <geom name="rindex1-rindex2" type="capsule" fromto="0 0 0 0.001150920987 -0.03014850616 -0.01115420461"  size="0.006" />
                                                <joint name="r_index1" type="hinge" pos="0 0 0" axis="0 1 0" range="-3.141592 3.141592" damping="5" stiffness="0" armature="0.02" />
                                                <joint name="r_index2" type="hinge" pos="0 0 0" axis="0 0 1" range="-3.141592 3.141592" damping="5" stiffness="0" armature="0.02" />
                                                <joint name="r_index3" type="hinge" pos="0 0 0" axis="1 0 0" range="-3.141592 3.141592" damping="5" stiffness="0" armature="0.02" />
                                                   
                                                <body name="right_index2" pos="0.001150920987 -0.03014850616 -0.01115420461" euler="0 0 0">
                                                    <geom name="rindex2-rindex3" type="capsule" fromto="0 0 0 -0.002432338893 -0.006504833698 -0.02157700062"  size="0.006" />
                                                    <joint name="r_index2-1" type="hinge" pos="0 0 0" axis="0 1 0" range="-3.141592 3.141592" damping="5" stiffness="0" armature="0.02" />
                                                    <joint name="r_index2-2" type="hinge" pos="0 0 0" axis="0 0 1" range="-3.141592 3.141592" damping="5" stiffness="0" armature="0.02" />
                                                    <joint name="r_index2-3" type="hinge" pos="0 0 0" axis="1 0 0" range="-3.141592 3.141592" damping="5" stiffness="0" armature="0.02" />
                                                   
                                                    <body name="right_index3" pos="-0.002432338893 -0.006504833698 -0.02157700062" euler="0 0 0">
                                                        <geom name="rindex3-rindextip" type="capsule" fromto="0 0 0 -0.002 -0.006 -0.02"  size="0.006" />
                                                        <joint name="r_index3-1" type="hinge" pos="0 0 0" axis="0 1 0" range="-3.141592 3.141592" damping="5" stiffness="0" armature="0.02" />
                                                        <joint name="r_index3-2" type="hinge" pos="0 0 0" axis="0 0 1" range="-3.141592 3.141592" damping="5" stiffness="0" armature="0.02" />
                                                        <joint name="r_index3-3" type="hinge" pos="0 0 0" axis="1 0 0" range="-3.141592 3.141592" damping="5" stiffness="0" armature="0.02" />
                                                        <body name="right_index4" pos="-0.002 -0.006 -0.02" euler="0 0 0"/>
                                                    </body>

                                                </body>
                                            </body>

                                            <body name="right_middle1" pos="-0.003733821213 -0.1073763967 -0.009421944618" euler="0 0 0">
                                                <geom name="rmiddle1-rmiddle2" type="capsule" fromto="0 0 0 -0.004641346633 -0.02647179365 -0.01521787047"  size="0.006" />
                                                <joint name="r_middle1" type="hinge" pos="0 0 0" axis="0 1 0" range="-3.141592 3.141592" damping="5" stiffness="0" armature="0.02" />
                                                <joint name="r_middle2" type="hinge" pos="0 0 0" axis="0 0 1" range="-3.141592 3.141592" damping="5" stiffness="0" armature="0.02" />
                                                <joint name="r_middle3" type="hinge" pos="0 0 0" axis="1 0 0" range="-3.141592 3.141592" damping="5" stiffness="0" armature="0.02" />
                                                   
                                                <body name="right_middle2" pos="-0.004641346633 -0.02647179365 -0.01521787047" euler="0 0 0">
                                                    <geom name="rmiddle2-rmiddle3" type="capsule" fromto="0 0 0 -0.001911155879 -0.005021512508 -0.02334678173"  size="0.006" />
                                                    <joint name="r_middle2-1" type="hinge" pos="0 0 0" axis="0 1 0" range="-3.141592 3.141592" damping="5" stiffness="0" armature="0.02" />
                                                    <joint name="r_middle2-2" type="hinge" pos="0 0 0" axis="0 0 1" range="-3.141592 3.141592" damping="5" stiffness="0" armature="0.02" />
                                                    <joint name="r_middle2-3" type="hinge" pos="0 0 0" axis="1 0 0" range="-3.141592 3.141592" damping="5" stiffness="0" armature="0.02" />
                                                   
                                                    <body name="right_middle3" pos="-0.001911155879 -0.005021512508 -0.02334678173" euler="0 0 0">
                                                        <geom name="rmiddle3-rmiddletip" type="capsule" fromto="0 0 0 -0.001 -0.005 -0.02"  size="0.006" />
                                                        <joint name="r_middle3-1" type="hinge" pos="0 0 0" axis="0 1 0" range="-3.141592 3.141592" damping="5" stiffness="0" armature="0.02" />
                                                        <joint name="r_middle3-2" type="hinge" pos="0 0 0" axis="0 0 1" range="-3.141592 3.141592" damping="5" stiffness="0" armature="0.02" />
                                                        <joint name="r_middle3-3" type="hinge" pos="0 0 0" axis="1 0 0" range="-3.141592 3.141592" damping="5" stiffness="0" armature="0.02" />
                                                        <body name="right_middle4" pos="-0.001 -0.005 -0.02" euler="0 0 0"/>
                                                    </body>
                                                </body>
                                            </body>

                                            <body name="right_ring1" pos="-0.02709873021 -0.09542346001 -0.01236194372" euler="0 0 0">
                                                <geom name="rring1-rring2" type="capsule" fromto="0 0 0 -0.001894876361 -0.02356100082 -0.01605695486"  size="0.006" />
                                                <joint name="r_ring1" type="hinge" pos="0 0 0" axis="0 1 0" range="-3.141592 3.141592" damping="5" stiffness="0" armature="0.02" />
                                                <joint name="r_ring2" type="hinge" pos="0 0 0" axis="0 0 1" range="-3.141592 3.141592" damping="5" stiffness="0" armature="0.02" />
                                                <joint name="r_ring3" type="hinge" pos="0 0 0" axis="1 0 0" range="-3.141592 3.141592" damping="5" stiffness="0" armature="0.02" />
                                                   
                                                <body name="right_ring2" pos="-0.001894876361 -0.02356100082 -0.01605695486" euler="0 0 0">
                                                    <geom name="rring2-rring3" type="capsule" fromto="0 0 0 8.15756619e-4 -0.004256904125 -0.02354767919"  size="0.006" />
                                                    <joint name="r_ring2-1" type="hinge" pos="0 0 0" axis="0 1 0" range="-3.141592 3.141592" damping="5" stiffness="0" armature="0.02" />
                                                    <joint name="r_ring2-2" type="hinge" pos="0 0 0" axis="0 0 1" range="-3.141592 3.141592" damping="5" stiffness="0" armature="0.02" />
                                                    <joint name="r_ring2-3" type="hinge" pos="0 0 0" axis="1 0 0" range="-3.141592 3.141592" damping="5" stiffness="0" armature="0.02" />
                                                   
                                                    <body name="right_ring3" pos="8.15756619e-4 -0.004256904125 -0.02354767919" euler="0 0 0">
                                                        <geom name="rring3-rringtip" type="capsule" fromto="0 0 0 8.1e-4 -0.004 -0.02"  size="0.006" />
                                                        <joint name="r_ring3-1" type="hinge" pos="0 0 0" axis="0 1 0" range="-3.141592 3.141592" damping="5" stiffness="0" armature="0.02" />
                                                        <joint name="r_ring3-2" type="hinge" pos="0 0 0" axis="0 0 1" range="-3.141592 3.141592" damping="5" stiffness="0" armature="0.02" />
                                                        <joint name="r_ring3-3" type="hinge" pos="0 0 0" axis="1 0 0" range="-3.141592 3.141592" damping="5" stiffness="0" armature="0.02" />
                                                        <body name="right_ring4" pos="8.1e-4 -0.004 -0.02" euler="0 0 0"/>
                                                    </body>
                                                </body>
                                            </body>

                                            <body name="right_pinky1" pos="-0.04350293428 -0.08202672005 -0.01763445139" euler="0 0 0">
                                                <geom name="rpinky1-rpinky2" type="capsule" fromto="0 0 0 -0.005374066532 -0.01212316751 -0.01444762945"  size="0.006" />
                                                <joint name="r_pinky1" type="hinge" pos="0 0 0" axis="0 1 0" range="-3.141592 3.141592" damping="5" stiffness="0" armature="0.02" />
                                                <joint name="r_pinky2" type="hinge" pos="0 0 0" axis="0 0 1" range="-3.141592 3.141592" damping="5" stiffness="0" armature="0.02" />
                                                <joint name="r_pinky3" type="hinge" pos="0 0 0" axis="1 0 0" range="-3.141592 3.141592" damping="5" stiffness="0" armature="0.02" />
                                                   
                                                <body name="right_pinky2" pos="-0.005374066532 -0.01212316751 -0.01444762945" euler="0 0 0">
                                                    <geom name="rpinky2-rpinky3" type="capsule" fromto="0 0 0 1.67131424e-4 -0.00379806757 -0.01885226369"  size="0.006" />
                                                    <joint name="r_pinky2-1" type="hinge" pos="0 0 0" axis="0 1 0" range="-3.141592 3.141592" damping="5" stiffness="0" armature="0.02" />
                                                    <joint name="r_pinky2-2" type="hinge" pos="0 0 0" axis="0 0 1" range="-3.141592 3.141592" damping="5" stiffness="0" armature="0.02" />
                                                    <joint name="r_pinky2-3" type="hinge" pos="0 0 0" axis="1 0 0" range="-3.141592 3.141592" damping="5" stiffness="0" armature="0.02" />
                                                   
                                                    <body name="right_pinky3" pos="1.67131424e-4 -0.00379806757 -0.01885226369" euler="0 0 0">
                                                        <geom name="rpinky3-rpinkytip" type="capsule" fromto="0 0 0 1.6e-4 -0.003 -0.018"  size="0.006" />
                                                        <joint name="r_pinky3-1" type="hinge" pos="0 0 0" axis="0 1 0" range="-3.141592 3.141592" damping="5" stiffness="0" armature="0.02" />
                                                        <joint name="r_pinky3-2" type="hinge" pos="0 0 0" axis="0 0 1" range="-3.141592 3.141592" damping="5" stiffness="0" armature="0.02" />
                                                        <joint name="r_pinky3-3" type="hinge" pos="0 0 0" axis="1 0 0" range="-3.141592 3.141592" damping="5" stiffness="0" armature="0.02" />
                                                        <body name="right_pinky4" pos="1.6e-4 -0.003 -0.018" euler="0 0 0"/>
                                                    </body>
                                                </body>
                                            </body>

                                            <body name="right_thumb1" pos="0.02586134896 -0.03861314058 -0.02107441425" euler="0 0 0">
                                                <geom name="rthumb1-rthumb2" type="capsule" fromto="0 0 0 0.01162325218 -0.02163636684 -0.01763868332"  size="0.006" />
                                                <joint name="r_thumb1" type="hinge" pos="0 0 0" axis="0 1 0" range="-3.141592 3.141592" damping="5" stiffness="0" armature="0.02" />
                                                <joint name="r_thumb2" type="hinge" pos="0 0 0" axis="0 0 1" range="-3.141592 3.141592" damping="5" stiffness="0" armature="0.02" />
                                                <joint name="r_thumb3" type="hinge" pos="0 0 0" axis="1 0 0" range="-3.141592 3.141592" damping="5" stiffness="0" armature="0.02" />
                                                   
                                                <body name="right_thumb2" pos="0.01162325218 -0.02163636684 -0.01763868332" euler="0 0 0">
                                                    <geom name="rthumb2-rthumb3" type="capsule" fromto="0 0 0 0.006546743214 -0.02400374413 -0.008353203535"  size="0.006" />
                                                    <joint name="r_thumb2-1" type="hinge" pos="0 0 0" axis="0 1 0" range="-3.141592 3.141592" damping="5" stiffness="0" armature="0.02" />
                                                    <joint name="r_thumb2-2" type="hinge" pos="0 0 0" axis="0 0 1" range="-3.141592 3.141592" damping="5" stiffness="0" armature="0.02" />
                                                    <joint name="r_thumb2-3" type="hinge" pos="0 0 0" axis="1 0 0" range="-3.141592 3.141592" damping="5" stiffness="0" armature="0.02" />
                                                   
                                                    <body name="right_thumb3" pos="0.006546743214 -0.02400374413 -0.008353203535" euler="0 0 0">
                                                        <geom name="rthumb3-rthumbtip" type="capsule" fromto="0 0 0 0.006 -0.02 -0.008"  size="0.006" />
                                                        <joint name="r_thumb3-1" type="hinge" pos="0 0 0" axis="0 1 0" range="-3.141592 3.141592" damping="5" stiffness="0" armature="0.02" />
                                                        <joint name="r_thumb3-2" type="hinge" pos="0 0 0" axis="0 0 1" range="-3.141592 3.141592" damping="5" stiffness="0" armature="0.02" />
                                                        <joint name="r_thumb3-3" type="hinge" pos="0 0 0" axis="1 0 0" range="-3.141592 3.141592" damping="5" stiffness="0" armature="0.02" />
                                                        <body name="right_thumb4" pos="0.006 -0.02 -0.008" euler="0 0 0"/>
                                                    </body>
                                                </body>
                                            </body>
                                        </body>
                                    </body>
                                </body>
                            </body>
                        </body>
                    </body>           
                </body>
            </body>
        </body>
    </worldbody>

    <actuator>
        <!-- Pelvis -->
        <motor name="pelvis1"       gear="200" joint="pelvis1" />
        <motor name="pelvis2"       gear="200" joint="pelvis2" />
        <motor name="pelvis3"       gear="200" joint="pelvis3" />

        <!-- Left Leg -->
        <motor name="l_hip1"       gear="200" joint="l_hip1" />
        <motor name="l_hip2"       gear="200" joint="l_hip2" />
        <motor name="l_hip3"       gear="200" joint="l_hip3" />

        <motor name="l_knee"       gear="200" joint="l_knee" />

        <motor name="l_ankle1"       gear="200" joint="l_ankle1" />
        <motor name="l_ankle2"       gear="200" joint="l_ankle2" />
        <motor name="l_ankle3"       gear="200" joint="l_ankle3" />

        <!-- Right Leg -->
        <motor name="r_hip1"       gear="200" joint="r_hip1" />
        <motor name="r_hip2"       gear="200" joint="r_hip2" />
        <motor name="r_hip3"       gear="200" joint="r_hip3" />

        <motor name="r_knee"       gear="200" joint="r_hip1" />
        
        <motor name="r_ankle1"       gear="200" joint="r_ankle1" />        
        <motor name="r_ankle2"       gear="200" joint="r_ankle2" />
        <motor name="r_ankle3"       gear="200" joint="r_ankle3" />

        <!-- Spine -->
        <motor name="spine1-1"            gear="200" joint="spine1-1" />
        <motor name="spine1-2"            gear="200" joint="spine1-2" />
        <motor name="spine1-3"            gear="200" joint="spine1-3" />

        <motor name="spine2-1"            gear="200" joint="spine2-1" />
        <motor name="spine2-2"            gear="200" joint="spine2-2" />
        <motor name="spine2-3"            gear="200" joint="spine2-3" />

        <motor name="spine3-1"            gear="200" joint="spine3-1" />
        <motor name="spine3-2"            gear="200" joint="spine3-2" />
        <motor name="spine3-3"            gear="200" joint="spine3-3" />

        <!-- Spine -->
        <motor name="neck1"            gear="200" joint="neck1" />
        <motor name="neck2"            gear="200" joint="neck2" />
        <motor name="neck3"            gear="200" joint="neck3" />

        <!-- Head -->
        <motor name="head1"             gear="200" joint="head1" />
        <motor name="head2"             gear="200" joint="head2" />
        <motor name="head3"             gear="200" joint="head3" />        

        <!-- Left Arm -->
        <motor name="l_collar1"         gear="100" joint="l_collar1" />
        <motor name="l_collar2"         gear="100" joint="l_collar2" />
        <motor name="l_collar3"         gear="100" joint="l_collar3" />

        <motor name="l_shoulder1"       gear="100" joint="l_shoulder1" />
        <motor name="l_shoulder2"       gear="100" joint="l_shoulder2" />
        <motor name="l_shoulder3"       gear="100" joint="l_shoulder3" />

        <motor name="l_elbow"           gear="200" joint="l_elbow" />

        <motor name="l_wrist1"          gear="100" joint="l_wrist1" />
        <motor name="l_wrist2"          gear="100" joint="l_wrist2" />
        <motor name="l_wrist3"          gear="100" joint="l_wrist3" />

        <!-- Left Finger -->
        <motor name="l_index3"          gear="100" joint="l_index3" />
        <motor name="l_index2-3"        gear="100" joint="l_index2-3" />
        <motor name="l_index3-3"        gear="100" joint="l_index3-3" />

        <motor name="l_middle3"         gear="100" joint="l_middle3" />
        <motor name="l_middle2-3"       gear="100" joint="l_middle2-3" />
        <motor name="l_middle3-3"       gear="100" joint="l_middle3-3" />

        <motor name="l_pinky3"          gear="100" joint="l_pinky3" />
        <motor name="l_pinky2-3"        gear="100" joint="l_pinky2-3" />
        <motor name="l_pinky3-3"        gear="100" joint="l_pinky3-3" />

        <motor name="l_ring3"           gear="100" joint="l_ring3" />
        <motor name="l_ring2-3"         gear="100" joint="l_ring2-3" />
        <motor name="l_ring3-3"         gear="100" joint="l_ring3-3" />

        <motor name="l_thumb1"          gear="100" joint="l_thumb1" />
        <motor name="l_thumb2"          gear="100" joint="l_thumb2" />  
        <motor name="l_thumb3"          gear="100" joint="l_thumb3" />    
        <motor name="l_thumb2-1"        gear="100" joint="l_thumb2-1" />
        <motor name="l_thumb2-2"        gear="100" joint="l_thumb2-2" />
        <motor name="l_thumb2-3"        gear="100" joint="l_thumb2-3" />
        <motor name="l_thumb3-1"        gear="100" joint="l_thumb3-1" />
        <motor name="l_thumb3-2"        gear="100" joint="l_thumb3-2" />
        <motor name="l_thumb3-3"        gear="100" joint="l_thumb3-3" />

        <!-- Right Arm -->
        <motor name="r_collar1"         gear="100" joint="r_collar1" />
        <motor name="r_collar2"         gear="100" joint="r_collar2" />
        <motor name="r_collar3"         gear="100" joint="r_collar3" />

        <motor name="r_shoulder1"       gear="100" joint="r_shoulder1" />
        <motor name="r_shoulder2"       gear="100" joint="r_shoulder2" />
        <motor name="r_shoulder3"       gear="100" joint="r_shoulder3" />

        <motor name="r_elbow"           gear="200" joint="r_elbow" />

        <motor name="r_wrist1"          gear="100" joint="r_wrist1" />
        <motor name="r_wrist2"          gear="100" joint="r_wrist2" />
        <motor name="r_wrist3"          gear="100" joint="r_wrist3" />

        <!-- Right Finger -->
        <motor name="r_index3"          gear="100" joint="r_index3" />
        <motor name="r_index2-3"        gear="100" joint="r_index2-3" />
        <motor name="r_index3-3"        gear="100" joint="r_index3-3" />

        <motor name="r_middle3"         gear="100" joint="r_middle3" />
        <motor name="r_middle2-3"       gear="100" joint="r_middle2-3" />
        <motor name="r_middle3-3"       gear="100" joint="r_middle3-3" />

        <motor name="r_pinky3"          gear="100" joint="r_pinky3" />
        <motor name="r_pinky2-3"        gear="100" joint="r_pinky2-3" />
        <motor name="r_pinky3-3"        gear="100" joint="r_pinky3-3" />

        <motor name="r_ring3"           gear="100" joint="r_ring3" />
        <motor name="r_ring2-3"         gear="100" joint="r_ring2-3" />
        <motor name="r_ring3-3"         gear="100" joint="r_ring3-3" />

        <motor name="r_thumb1"          gear="100" joint="r_thumb1" />
        <motor name="r_thumb2"          gear="100" joint="r_thumb2" />  
        <motor name="r_thumb3"          gear="100" joint="r_thumb3" />    
        <motor name="r_thumb2-1"        gear="100" joint="r_thumb2-1" />
        <motor name="r_thumb2-2"        gear="100" joint="r_thumb2-2" />
        <motor name="r_thumb2-3"        gear="100" joint="r_thumb2-3" />
        <motor name="r_thumb3-1"        gear="100" joint="r_thumb3-1" />
        <motor name="r_thumb3-2"        gear="100" joint="r_thumb3-2" />
        <motor name="r_thumb3-3"        gear="100" joint="r_thumb3-3" />
    </actuator>

    <contact>
        <exclude body1="neck" body2="right_shoulder"/>
        <exclude body1="spine3" body2="right_shoulder"/>
        <exclude body1="right_shoulder" body2="right_elbow"/>
        <exclude body1="right_elbow" body2="right_wrist"/>

        <exclude body1="neck" body2="left_shoulder"/>
        <exclude body1="spine3" body2="left_shoulder"/>
        <exclude body1="left_shoulder" body2="left_elbow"/>
        <exclude body1="left_elbow" body2="left_wrist"/>

        <exclude body1="neck" body2="spine3"/>
        <exclude body1="spine1" body2="pelvis"/>
        <exclude body1="pelvis" body2="base"/>

        <exclude body1="pelvis" body2="right_hip"/>
        <exclude body1="right_hip" body2="right_knee"/>
        <exclude body1="right_knee" body2="right_ankle"/>

        <exclude body1="pelvis" body2="left_hip"/>
        <exclude body1="left_hip" body2="left_knee"/>
        <exclude body1="left_knee" body2="left_ankle"/>
    </contact>

</mujoco>